[2023-07-19T21:47:47.057+0000] {taskinstance.py:1103} INFO - Dependencies all met for dep_context=non-requeueable deps ti=<TaskInstance: ETL_stock_data_google_DAG.send_completion_email manual__2023-07-19T21:46:40.858683+00:00 [queued]>
[2023-07-19T21:47:47.069+0000] {taskinstance.py:1103} INFO - Dependencies all met for dep_context=requeueable deps ti=<TaskInstance: ETL_stock_data_google_DAG.send_completion_email manual__2023-07-19T21:46:40.858683+00:00 [queued]>
[2023-07-19T21:47:47.070+0000] {taskinstance.py:1308} INFO - Starting attempt 1 of 1
[2023-07-19T21:47:47.087+0000] {taskinstance.py:1327} INFO - Executing <Task(PythonOperator): send_completion_email> on 2023-07-19 21:46:40.858683+00:00
[2023-07-19T21:47:47.092+0000] {standard_task_runner.py:57} INFO - Started process 233 to run task
[2023-07-19T21:47:47.025+0000] {standard_task_runner.py:84} INFO - Running: ['***', 'tasks', 'run', 'ETL_stock_data_google_DAG', 'send_completion_email', 'manual__2023-07-19T21:46:40.858683+00:00', '--job-id', '51', '--raw', '--subdir', 'DAGS_FOLDER/ETL_stock_data_google_DAG.py', '--cfg-path', '/tmp/tmpcqz8nwy9']
[2023-07-19T21:47:47.030+0000] {standard_task_runner.py:85} INFO - Job 51: Subtask send_completion_email
[2023-07-19T21:47:47.088+0000] {task_command.py:410} INFO - Running <TaskInstance: ETL_stock_data_google_DAG.send_completion_email manual__2023-07-19T21:46:40.858683+00:00 [running]> on host 90317fb99301
[2023-07-19T21:47:47.190+0000] {taskinstance.py:1545} INFO - Exporting env vars: AIRFLOW_CTX_DAG_OWNER='fvinciguerra' AIRFLOW_CTX_DAG_ID='ETL_stock_data_google_DAG' AIRFLOW_CTX_TASK_ID='send_completion_email' AIRFLOW_CTX_EXECUTION_DATE='2023-07-19T21:46:40.858683+00:00' AIRFLOW_CTX_TRY_NUMBER='1' AIRFLOW_CTX_DAG_RUN_ID='manual__2023-07-19T21:46:40.858683+00:00'
[2023-07-19T21:47:47.193+0000] {taskinstance.py:1824} ERROR - Task failed with exception
Traceback (most recent call last):
  File "/home/airflow/.local/lib/python3.8/site-packages/airflow/operators/python.py", line 181, in execute
    return_value = self.execute_callable()
  File "/home/airflow/.local/lib/python3.8/site-packages/airflow/operators/python.py", line 198, in execute_callable
    return self.python_callable(*self.op_args, **self.op_kwargs)
TypeError: send_completion_email() missing 1 required positional argument: 'context'
[2023-07-19T21:47:47.204+0000] {taskinstance.py:1345} INFO - Marking task as FAILED. dag_id=ETL_stock_data_google_DAG, task_id=send_completion_email, execution_date=20230719T214640, start_date=20230719T214747, end_date=20230719T214747
[2023-07-19T21:47:47.219+0000] {standard_task_runner.py:104} ERROR - Failed to execute job 51 for task send_completion_email (send_completion_email() missing 1 required positional argument: 'context'; 233)
[2023-07-19T21:47:47.260+0000] {local_task_job_runner.py:225} INFO - Task exited with return code 1
[2023-07-19T21:47:47.280+0000] {taskinstance.py:2653} INFO - 0 downstream tasks scheduled from follow-on schedule check
