[2023-07-19T21:29:05.500+0000] {taskinstance.py:1103} INFO - Dependencies all met for dep_context=non-requeueable deps ti=<TaskInstance: ETL_stock_data_google_DAG.send_completion_email manual__2023-07-19T21:27:57.858815+00:00 [queued]>
[2023-07-19T21:29:05.512+0000] {taskinstance.py:1103} INFO - Dependencies all met for dep_context=requeueable deps ti=<TaskInstance: ETL_stock_data_google_DAG.send_completion_email manual__2023-07-19T21:27:57.858815+00:00 [queued]>
[2023-07-19T21:29:05.514+0000] {taskinstance.py:1308} INFO - Starting attempt 1 of 1
[2023-07-19T21:29:05.531+0000] {taskinstance.py:1327} INFO - Executing <Task(PythonOperator): send_completion_email> on 2023-07-19 21:27:57.858815+00:00
[2023-07-19T21:29:05.535+0000] {standard_task_runner.py:57} INFO - Started process 228 to run task
[2023-07-19T21:29:05.538+0000] {standard_task_runner.py:84} INFO - Running: ['***', 'tasks', 'run', 'ETL_stock_data_google_DAG', 'send_completion_email', 'manual__2023-07-19T21:27:57.858815+00:00', '--job-id', '39', '--raw', '--subdir', 'DAGS_FOLDER/ETL_stock_data_google_DAG.py', '--cfg-path', '/tmp/tmp202teu3k']
[2023-07-19T21:29:05.543+0000] {standard_task_runner.py:85} INFO - Job 39: Subtask send_completion_email
[2023-07-19T21:29:05.601+0000] {task_command.py:410} INFO - Running <TaskInstance: ETL_stock_data_google_DAG.send_completion_email manual__2023-07-19T21:27:57.858815+00:00 [running]> on host 90317fb99301
[2023-07-19T21:29:05.696+0000] {taskinstance.py:1545} INFO - Exporting env vars: AIRFLOW_CTX_DAG_OWNER='fvinciguerra' AIRFLOW_CTX_DAG_ID='ETL_stock_data_google_DAG' AIRFLOW_CTX_TASK_ID='send_completion_email' AIRFLOW_CTX_EXECUTION_DATE='2023-07-19T21:27:57.858815+00:00' AIRFLOW_CTX_TRY_NUMBER='1' AIRFLOW_CTX_DAG_RUN_ID='manual__2023-07-19T21:27:57.858815+00:00'
[2023-07-19T21:29:05.697+0000] {taskinstance.py:1824} ERROR - Task failed with exception
Traceback (most recent call last):
  File "/home/airflow/.local/lib/python3.8/site-packages/airflow/operators/python.py", line 181, in execute
    return_value = self.execute_callable()
  File "/home/airflow/.local/lib/python3.8/site-packages/airflow/operators/python.py", line 198, in execute_callable
    return self.python_callable(*self.op_args, **self.op_kwargs)
TypeError: send_completion_email() missing 1 required positional argument: 'context'
[2023-07-19T21:29:05.707+0000] {taskinstance.py:1345} INFO - Marking task as FAILED. dag_id=ETL_stock_data_google_DAG, task_id=send_completion_email, execution_date=20230719T212757, start_date=20230719T212905, end_date=20230719T212905
[2023-07-19T21:29:05.722+0000] {standard_task_runner.py:104} ERROR - Failed to execute job 39 for task send_completion_email (send_completion_email() missing 1 required positional argument: 'context'; 228)
[2023-07-19T21:29:05.763+0000] {local_task_job_runner.py:225} INFO - Task exited with return code 1
[2023-07-19T21:29:05.781+0000] {taskinstance.py:2653} INFO - 0 downstream tasks scheduled from follow-on schedule check
